Workbook
Name EAR_Machines: 'Rate-IndividualMachines'!$K$2:$K$109
Name EAR_01___Public_Utilities: 'Rate-SubGroup'!$A$2:$A$58
Name EAR_02___Industrial_Plant_Utilities: 'Rate-SubGroup'!$A$59:$A$70
Name EAR_03___Mining_Industry: 'Rate-SubGroup'!$A$71:$A$74
Name EAR_04___Chemical_Industry: 'Rate-SubGroup'!$A$75:$A$92
Name EAR_05___Metal_Industry: 'Rate-SubGroup'!$A$93:$A$99
Name EAR_06___Building_Industry: 'Rate-SubGroup'!$A$100:$A$104
Name EAR_07___Timber___Wood: 'Rate-SubGroup'!$A$105:$A$107
Name EAR_08___Pulp___Paper: 'Rate-SubGroup'!$A$108:$A$109
Name EAR_09___Printing___Packing: 'Rate-SubGroup'!$A$110:$A$111
Name EAR_10___Leather_Industry: 'Rate-SubGroup'!$A$112:$A$113
Name EAR_11___Textile_Industry: 'Rate-SubGroup'!$A$114:$A$120
Name EAR_12___Plastic___Rubber: 'Rate-SubGroup'!$A$121:$A$126
Name EAR_13___Food__Vegetable_: 'Rate-SubGroup'!$A$127:$A$135
Name EAR_14___Food__Animal_: 'Rate-SubGroup'!$A$136:$A$138
Name EAR_15___Food_Refrigeration: 'Rate-SubGroup'!$A$139:$A$140
Name EAR_16___Transport___Warehouses: 'Rate-SubGroup'!$A$141:$A$144
Name EAR_17___Public_Services: 'Rate-SubGroup'!$A$145:$A$147
Name EAR_18___Hospitals___Hotels: 'Rate-SubGroup'!$A$148:$A$149
Name EAR_19___Farming___Agriculture: 'Rate-SubGroup'!$A$150:$A$152
Name EAR_Clauses: 'Rate-Clauses'!$I$2:$I$27
Name EAR_Groups: 'Rate-SubGroup'!$N$2:$N$20
Name HZP_01: 'Hazard-Cities-2800'!$C$2:$C$22
Name HZP_02: 'Hazard-Cities-2800'!$C$23:$C$41
Name HZP_03: 'Hazard-Cities-2800'!$C$42:$C$56
Name HZP_04: 'Hazard-Cities-2800'!$C$57:$C$88
Name HZP_05: 'Hazard-Cities-2800'!$C$89:$C$96
Name HZP_06: 'Hazard-Cities-2800'!$C$97:$C$116
Name HZP_07: 'Hazard-Cities-2800'!$C$117:$C$142
Name HZP_08: 'Hazard-Cities-2800'!$C$143:$C$155
Name HZP_09: 'Hazard-Cities-2800'!$C$156:$C$181
Name HZP_10: 'Hazard-Cities-2800'!$C$182:$C$191
Name HZP_11: 'Hazard-Cities-2800'!$C$192:$C$221
Name HZP_12: 'Hazard-Cities-2800'!$C$222:$C$231
Name HZP_13: 'Hazard-Cities-2800'!$C$232:$C$252
Name HZP_14: 'Hazard-Cities-2800'!$C$253:$C$274
Name HZP_15: 'Hazard-Cities-2800'!$C$275:$C$304
Name HZP_16: 'Hazard-Cities-2800'!$C$305:$C$311
Name HZP_17: 'Hazard-Cities-2800'!$C$312:$C$316
Name HZP_18: 'Hazard-Cities-2800'!$C$317:$C$325
Name HZP_19: 'Hazard-Cities-2800'!$C$326:$C$347
Name HZP_20: 'Hazard-Cities-2800'!$C$348:$C$360
Name HZP_21: 'Hazard-Cities-2800'!$C$361:$C$373
Name HZP_22: 'Hazard-Cities-2800'!$C$374:$C$382
Name HZP_23: 'Hazard-Cities-2800'!$C$383:$C$394
Name HZP_24: 'Hazard-Cities-2800'!$C$395:$C$402
Name HZP_25: 'Hazard-Cities-2800'!$C$403:$C$423
Name HZP_26: 'Hazard-Cities-2800'!$C$424:$C$440
Name HZP_27: 'Hazard-Cities-2800'!$C$441:$C$444
Name HZP_28: 'Hazard-Cities-2800'!$C$445:$C$454
Name HZP_29: 'Hazard-Cities-2800'!$C$455:$C$472
Name HZP_30: 'Hazard-Cities-2800'!$C$473:$C$490

Sheet محاسبه-ساده
A1: 🧮 محاسبهٔ سریع حق‌بیمهٔ EAR
A3: =IF(AND(LEFT(Data!E75,1)="✓",LEFT(Data!E76,1)="✓",LEFT(Data!E77,1)="✓",LEFT(Data!E79,1)="✓",LEFT(Data!E80,1)="✓",LEFT(Data!E93,1)="✓"),"🟢 آماده محاسبه — همهٔ ورودی‌ها معتبرند","🔴 یکی از ورودی‌ها را بررسی کنید (شیت Data ردیف‌های K را ببینید)") -> 🟢 آماده محاسبه — همهٔ ورودی‌ها معتبرند
A4: نرخ فنی نهایی (بدون TPL) | C4: =Data!D60 -> 4.1
A5: حق‌بیمهٔ کل قابل‌پرداخت (﷼) | C5: =Data!E73 -> 165480129095
A8: ۱) مشخصات پروژه
B9: دامنهٔ پروژه (Project Scope) | C9: کل پروژه (Entire Project) | D9: کل پروژه = جداول سفید · ماشین‌آلات منفرد = جداول آبی (بند ۲.۵ سوییس‌ری)
B10: گروه صنعتی | C10: 05 — Metal Industry | D10: از فهرست انتخاب کنید
B11: زیرگروه پروژه ⟨فقط حالت کل پروژه⟩ | C11: 12.5 Paint factories and processing of comparable products | D11: بر اساس گروه بالا فیلتر می‌شود
B12: ماشین منفرد ⟨فقط حالت ماشین‌آلات منفرد⟩ | C12: 02.0.1 — Boiler feed pumps, incl. drive — turbine driven | D12: از جداول آبی — ۱۰۸ ماشین، با کد EAR برای جلوگیری از هم‌نامی
B13: مدت کل پروژه (ماه) ⟨فقط حالت کل پروژه⟩ | C13: 15 | D13: نصب + آزمایش، جمعاً
B14: ماه‌های نصب ⟨ماشین منفرد⟩ | C14: 3 | D14: نرخ پایه شامل ۳ ماه است · قابل تمدید تا حداکثر ۹ ماه (بند ۲.۵)
B15: ماه‌های آزمایش ⟨ماشین منفرد⟩ | C15: 1 | D15: نرخ پایه شامل ۱ ماه است · قابل تمدید تا حداکثر ۳ ماه (بند ۲.۵)
B16: استان | C16: قم | D16: از فهرست انتخاب کنید
B17: شهرستان | C17: قم | D17: ="بر اساس استان فیلتر می‌شود · سطح خطر زلزلهٔ شهر انتخابی: "&Data!E7 -> بر اساس استان فیلتر می‌شود · سطح خطر زلزلهٔ شهر انتخابی: زیاد
A19: ۲) مبلغ‌ها
B20: مبلغ بیمه — ارزش کل پروژه (﷼) | C20: 30638794500000 | D20: مبنای اصلی محاسبهٔ حق‌بیمه
B21: سقف مسئولیت شخص ثالث TPL (﷼) | C21: 6127758900000 | D21: سقف غرامت مسئولیت مدنی
B22: پوشش مسئولیت شخص ثالث (TPL) اصلاً وجود دارد؟ | C22: Yes | D22: اگر No باشد، کل حق‌بیمهٔ TPL (پایه + مسئولیت متقابل) صفر می‌شود و ردیف‌های ۲۶ تا ۲۸ نادیده گرفته می‌شوند
A23: ۳) گزینه‌های رایج (بیشتر پروژه‌ها این‌ها را دارند)
B24: آزمایش/راه‌اندازی (Testing) شامل شود؟ | C24: Yes | D24: اگر پروژه دورهٔ آزمایش دارد
B25: طبقهٔ نگهداری | C25: Heavy | D25: سبک (Light) یا سنگین/شیمیایی (Heavy)
B26: نگهداری ساده — مدت (ماه) | C26: 0 | D26: ۰ یعنی ندارد
B27: نگهداری گسترده — مدت (ماه) | C27: 0 | D27: ۰ یعنی ندارد
B28: کلاس حساسیت تجهیزات در برابر زلزله (۱ تا ۴) | C28: 2 | D28: ۱=غیرحساس … ۴=بسیار حساس
B29: کلاس مقاومت سازهٔ ساختمان (۱ تا ۶) | C29: 3 | D29: ۱=فولادی سبک … ۶=بنایی آجری
B30: ردهٔ ریسک فنی TPL | C30: III (Heavy) | D30: سبک / متوسط / سنگین
B31: ردهٔ محیط اطراف کارگاه (TPL) | C31: b — outer town (moderate density) | D31: سایت ایزوله / حومه / مرکز شهر
B32: مسئولیت متقابل (Cross Liability) شامل شود؟ | C32: Yes | D32: ٪۳۵ اضافه بر حق‌بیمهٔ TPL
A34: ۴) گزینه‌های تکمیلی (فقط اگر پروژه دارد وارد کنید)
B35: ریسک سازندهٔ تجهیزات — نقص مواد/کارگری (ماه) | C35: 0 | D35: ۰ = ندارد
B36: ریسک سازندهٔ تجهیزات — نقص طراحی (ماه) | C36: 0 | D36: ۰ = ندارد
B37: هزینهٔ تسریع — درصد از نرخ کار (اعشاری) | C37: 0 | D37: مثلاً ۰.۰۷۵ برای ۷.۵٪ · ۰ = ندارد
B38: شورش و اعتصاب — نرخ آتش‌نشانی (‰) | C38: 0 | D38: از بازار بیمهٔ آتش‌سوزی محلی بگیرید · ۰ = ندارد
B39: شورش و اعتصاب — دوره | C39: Testing/Commissioning period | D39: نصب یا آزمایش
B40: هوابرد — سقف تعهد (﷼) | C40: 0 | D40: ۰ = ندارد
B41: هوابرد — نرخ (‰) | C41: 0 | D41: ۵‰ زیر ۲۰۰۰ مایل، تا ۲۰‰ فاصلهٔ بیشتر
B42: انبارداری پیش از نصب — ارزش کالا (﷼) | C42: 0 | D42: ۰ = ندارد
B43: انبارداری پیش از نصب — مدت (ماه) | C43: 0 | D43: ۰ = ندارد
B44: ترانزیت زمینی — ارزش کالای در حال حمل (﷼) | C44: 0 | D44: ۰ = ندارد
B45: رفع نخاله — سقف هر رویداد (﷼) | C45: 0 | D45: ۰ = ندارد
...

Sheet Data
A1: EAR (Erection All Risks) — Premium Rating Engine · Swiss Re EAR methodology
A2: # | B2: Input / Parameter | C2: Selected Value | E2: Computed | F2: Notes / Swiss Re guidance
A3: A RISK CLASSIFICATION
A4: A1 | B4: Industry Group | C4: ='محاسبه-ساده'!C10 -> 05 — Metal Industry | F4: Select industry group. Drives the sub-group list.
A5: A2 | B5: Project Sub-Group | C5: ='محاسبه-ساده'!C11 -> 12.5 Paint factories and processing of comparable products | F5: Auto-filtered by group. Full EAR name incl. size band — this drives all base rates. | I5: =SUBSTITUTE(SUBSTITUTE(SUBSTITUTE(SUBSTITUTE(SUBSTITUTE(SUBSTITUTE(SUBSTITUTE(C4," ","_"),"-","_"),"—","_"),"(","_"),")","_"),"&","_"),"/","_") -> 05___Metal_Industry | J5: ="EAR_"&I5 -> EAR_05___Metal_Industry
A6: A3 | B6: Project Duration (months) | C6: ='محاسبه-ساده'!C13 -> 15 | F6: Total erection + testing period. Drives month-band rate build-up.
A7: A4 | B7: Province (Iran) — Standard 2800 | C7: ='محاسبه-ساده'!C16 -> قم | E7: =IFERROR(INDEX('Hazard-Cities-2800'!$E:$E,MATCH($C$8&" — "&$C$7,'Hazard-Cities-2800'!$B:$B,0)),"#not found") -> زیاد | F7: Select Province here; City/Town auto-filters in the row below (C8). Hazard level (E7) is read from the Standard 2800 (4th ed.) Appendix 1 classification, 489 county-seat points — sheet 'Hazard-Cities-2800'.
A8: A5 | B8: City/Town (auto-filtered by Province) | C8: ='محاسبه-ساده'!C17 -> قم | F8: City/town auto-filtered to the Province selected in C7 (Standard 2800 Appendix 1 classification, 489 county-seat points — sheet 'Hazard-Cities-2800'). Hazard level result shown in E7. | H8: =IFERROR(INDEX('Hazard-Province-Index'!$C:$C,MATCH($C$7,'Hazard-Province-Index'!$B:$B,0)),"#unknown province") -> HZP_17 | I8: Safe defined-name code driving the C8 dropdown (INDIRECT target) — same pattern as I5/J5 for Group→Sub-group.
A9: B BASE ERECTION RATE (from Rate-SubGroup, by month-band)
A10: B1 | B10: Base Erection Rate (banded, ‰) | E10: =IFERROR(IF($C$6<=1,INDEX('Rate-SubGroup'!$B$2:$B$152,MATCH($C$5,'Rate-SubGroup'!$A$2:$A$152,0)),IF($C$6<=12,INDEX('Rate-SubGroup'!$B$2:$B$152,MATCH($C$5,'Rate-SubGroup'!$A$2:$A$152,0))+($C$6-1)*INDEX('Rate-SubGroup'!$C$2:$C$152,MATCH($C$5,'Rate-SubGroup'!$A$2:$A$152,0)),IF($C$6<=24,INDEX('Rate-SubGroup'!$B$2:$B$152,MATCH($C$5,'Rate-SubGroup'!$A$2:$A$152,0))+11*INDEX('Rate-SubGroup'!$C$2:$C$152,MATCH($C$5,'Rate-SubGroup'!$A$2:$A$152,0))+($C$6-12)*INDEX('Rate-SubGroup'!$D$2:$D$152,MATCH($C$5,'Rate-SubGroup'!$A$2:$A$152,0)),INDEX('Rate-SubGroup'!$B$2:$B$152,MATCH($C$5,'Rate-SubGroup'!$A$2:$A$152,0))+11*INDEX('Rate-SubGroup'!$C$2:$C$152,MATCH($C$5,'Rate-SubGroup'!$A$2:$A$152,0))+12*INDEX('Rate-SubGroup'!$D$2:$D$152,MATCH($C$5,'Rate-SubGroup'!$A$2:$A$152,0))+($C$6-24)*INDEX('Rate-SubGroup'!$E$2:$E$152,MATCH($C$5,'Rate-SubGroup'!$A$2:$A$152,0))))),"#sub-group not found") -> 3.025 | F10: 1st-month Code1 + 0.10/0.05/0.025 bands per Swiss Re month structure.
A11: B2 | B11: Minimum Rate (floor, ‰) | E11: =IFERROR(INDEX('Rate-SubGroup'!$H$2:$H$152,MATCH($C$5,'Rate-SubGroup'!$A$2:$A$152,0)),"") -> 3.65 | F11: Erection rate cannot fall below this Swiss Re floor.
A12: B3 | B12: Hot Testing / Commissioning included? | C12: ='محاسبه-ساده'!C24 -> Yes | E12: =IF($I$86="M",0,IF($C$12="Yes",IFERROR(INDEX('Rate-SubGroup'!$F$2:$F$152,MATCH($C$5,'Rate-SubGroup'!$A$2:$A$152,0)),0),0)) -> 0.45 | F12: First-month testing rate (Rate-SubGroup col F) if Yes.
A13: B4 | B13: Effective Erection Rate (‰) | E13: =IF($I$86="M",$E$91,IFERROR(MAX(E10,E11),0)) -> 3.65 | F13: MAX(banded base, minimum-rate floor).
A14: B5 | B14: Reference Rate (‰) | E14: =IF($I$86="M",$E$92,IFERROR(INDEX('Rate-SubGroup'!$G$2:$G$152,MATCH($C$5,'Rate-SubGroup'!$A$2:$A$152,0)),0)) -> 3 | F14: Basis for Manufacturer's-Risk & maintenance loadings (col G).
A15: C EARTHQUAKE LOADING (Swiss Re real method: E = E1 × E2, Table E monthly rate × project duration) | G15: Helper calculations (not part of visible rate build-up):
A16: EQ1 | B16: Plant Sensitivity Class (Table E1, 1–4) | C16: ='محاسبه-ساده'!C28 -> 2 | E16: =IFERROR(INDEX('Rate-EQ-SwissRe'!$D$5:$D$8,MATCH($C$16,'Rate-EQ-SwissRe'!$A$5:$A$8,0)),"#invalid class") -> 2 | F16: Select 1-4 per Rate-EQ-SwissRe sheet Table E1 (equipment sensitivity). Returns factor E1.
A17: EQ2 | B17: Structure Factor Class (Table E2, 1–6) | C17: ='محاسبه-ساده'!C29 -> 3 | E17: =IFERROR(INDEX('Rate-EQ-SwissRe'!$D$12:$D$17,MATCH($C$17,'Rate-EQ-SwissRe'!$A$12:$A$17,0)),"#invalid class") -> 2 | F17: Select 1-6 per Rate-EQ-SwissRe sheet Table E2 (building/structure resistance). Returns factor E2.
A18: EQ3 | B18: Combined Sensitivity Factor E = E1 × E2 | E18: =E16*E17 -> 4 | F18: Real Swiss Re combined factor (was hardcoded/deprecated before this revision). | G18: =IF(E18<=1,1,IF(E18<=1.5,1.5,IF(E18<=2,2,IF(E18<=2.5,2.5,IF(E18<=3,3,IF(E18<=4,4,IF(E18<=5,5,IF(E18<=6,6,IF(E18<=8,8,IF(E18<=10,10,IF(E18<=12.5,12.5,IF(E18<=15,15,20)))))))))))) -> 4 | H18: E rounded UP to nearest Table E value (conservative assumption — see Rate-EQ-SwissRe notes)
A19: EQ4 | B19: Swiss Re Zone (derived from city hazard level, Standard 2800) | E19: =IFERROR(INDEX('Rate-EQ-SwissRe'!$B$21:$B$24,MATCH($E$7,'Rate-EQ-SwissRe'!$A$21:$A$24,0)),"#level not mapped") -> C | F19: Maps the city's Standard 2800 hazard level (E7) to a Swiss Re zone per the user-approved table in 'Rate-EQ-SwissRe' (خیلی‌زیاد→B, زیاد→C, متوسط→D, کم→E). Replaces the old 1.00/1.15 provincial multiplier entirely. | G19: =IFERROR(INDEX('Rate-EQ-SwissRe'!$B$29:$F$41,MATCH($G$18,'Rate-EQ-SwissRe'!$A$29:$A$41,0),MATCH($E$19,{"A","B","C","D","E"},0)),0) -> 0 | H19: Monthly earthquake rate (‰) from Table E, for rounded E and derived Zone
A20: EQ5 | B20: Earthquake Exclusion clause? | C20: ='محاسبه-ساده'!C48 -> No | F20: If Yes, EQ loading is forced to 0 (and must be excluded from TPL too).
A21: EQ6 | B21: Earthquake Loading (‰) | E21: =IF($C$20="Yes",0,ROUND($G$19*$C$6,4)) -> 0 | F21: Loading = monthly rate from Table E (G19) x project duration in months (C6, erection+testing). Real Swiss Re monthly-accrual method - replaces the old flat (rate x (loading factor - 1)) formula. Section I rate-summary structure (D59:D63) is unchanged.
A22: D EXISTING PROPERTY (premium on its own limit per event)
A23: D1 | B23: نگهداری گسترده — مدت (ماه) | C23: ='محاسبه-ساده'!C46 -> Not included — existing property not covered | D23: ='محاسبه-ساده'!C47 -> 0 | E23: =IFERROR(VLOOKUP($C$23,'Rate-Asset'!$A:$B,2,0),0) -> 0 | F23: Rate ‰ per event (Rate-Asset, ﷼ column). Premium applies to the limit, not the SI.
A24: D2 | B24: Existing Property — Limit per event (﷼) → Premium | E24: =ROUND(E23*D23/1000,0) -> 0 | F24: Enter limit per event in D23. Premium = rate × limit / 1000.
A25: E EXTENSIONS — RATE LOADINGS (‰ added to the MD rate, on contract value)
A26: ▸ | B26: Enter 0 (or “No”) to exclude an item. Loadings here are ‰ on the Sum Insured.
A27: E1 | B27: Manufacturer's Risk — Material/Workmanship (6.1.1): test/maint months | C27: ='محاسبه-ساده'!C35 -> 0 | D27: سایت ایزوله / حومه / مرکز شهر | E27: =IF(C27<=0,0,IF(C27<=3,0.05,IF(C27<=6,0.075,0.1))*E14) -> 0 | F27: 5% (1–3 mo) / 7.5% (4–6) / 10% (7+) of Ref.Rate.
A28: E2 | B28: Manufacturer's Risk — Defective Design (6.1.2): test/maint months | C28: ='محاسبه-ساده'!C36 -> 0 | E28: =IF(C28<=0,0,IF(C28<=3,0.05,IF(C28<=6,0.075,0.1))*E14) -> 0 | F28: Same scale as 6.1.1, on Ref.Rate.
A29: E3 | B29: Maintenance industry class | C29: ='محاسبه-ساده'!C25 -> Heavy | F29: Light vs power/chemical/heavy — sets maintenance % scale.
A30: E4 | B30: Visits Maintenance (6.2.1): maintenance months | C30: ='محاسبه-ساده'!C26 -> 0 | E30: =IF(C30<=0,0,IF(C29="Heavy",0.075,0.05)*E14*(C30/12)) -> 0 | F30: 5% light / 7.5% heavy of Ref.Rate per 12-mo period (pro-rata).
A31: E5 | B31: Extended Maintenance (6.2.2): maintenance months | C31: ='محاسبه-ساده'!C27 -> 0 | E31: =IF(C31<=0,0,IF(C29="Heavy",0.125,0.075)*E14*(C31/12)) -> 0 | F31: 7.5% light / 12.5% heavy of Ref.Rate per 12-mo period (pro-rata).
A32: E6 | B32: Expediting Costs (5.3): % of works rate | C32: ='محاسبه-ساده'!C37 -> 0 | E32: =IF(C32<=0,0,C32*E13) -> 0 | F32: 5–10% of the erection (works) rate. Enter as decimal, e.g. 0.075.
A33: E7 | B33: Riot and Strike (6.4): Fire Dept / FOC riot-and-strike rate (‰) | C33: ='محاسبه-ساده'!C38 -> 0 | F33: This is an EXTERNAL rate — Swiss Re does not tabulate it. Obtain the local Fire Department's (or FOC London-style) riot-and-strike rate for the property/plant, then enter it here as a ‰ figure. Excludes civil commotion unless separately agreed with the Reinsurer.
A34: E8 | B34: Riot and Strike — period basis | C34: ='محاسبه-ساده'!C39 -> Testing/Commissioning period | E34: =IF(C33<=0,0,C33*IF(C34="Testing/Commissioning period",1,0.5)) -> 0 | F34: Testing/Commissioning period = 100% of the rate above (confirmed, EAR Rating Guide Sec.9 item 6.4). Erection period = 50% shown here, but this figure could NOT be verified in the uploaded Swiss Re source after two independent searches — flagged as insufficient evidence; confirm with reinsurer before relying on it.
A35: E9 | B35: Rate-loadings sub-total (‰) | E35: =E27+E28+E30+E31+E32+E34 -> 0 | F35: Sum of the loadings above.
A36: F EXTENSIONS — PREMIUM ADD-ONS (c-units, each on its own basis)
A37: ▸ | B37: These apply to a separate limit/value, NOT the SI, so they are priced as premiums (﷼), not ‰.
A38: F1 | B38: Air Freight (5.4): aggregate limit (C, ﷼) · rate ‰ (D) | C38: ='محاسبه-ساده'!C40 -> 0 | D38: ='محاسبه-ساده'!C41 -> 0 | E38: =ROUND(D38*C38/1000,0) -> 0 | F38: 5‰ <2000 mi, up to 20‰ longer. Premium = rate × limit / 1000.
A39: F2 | B39: Storage Pre-Erection (5.5): value stored (C, ﷼) · months (D) | C39: ='محاسبه-ساده'!C42 -> 0 | D39: ='محاسبه-ساده'!C43 -> 0 | E39: =ROUND(0.1*C39*D39/1000,0) -> 0 | F39: Min 0.1‰/month on value stored.
A40: F3 | B40: Inland Transit (6.5): value transported (C, ﷼) | C40: ='محاسبه-ساده'!C44 -> 0 | E40: =ROUND(1*C40/1000,0) -> 0 | F40: Min 1‰ on total value transported (marine specialist rate).
...

Sheet Rate-SubGroup
A1: Project Sub-Group | B1: Code1 | C1: Code2 | D1: Code3 | E1: Code4 | F1: Hot_test | G1: Ref_Rate | H1: Min. Rate | I1: Gen. Excess (c-units) All Events | J1: AoG / Test / Maint. Excess (c-units) | K1: Gen. Excess (﷼) | L1: AoG/Test/Maint Excess (﷼) | N1: _groups
A2: 01.1.1 Boilerhouse installations — natural circulation, ≤250 t/h (boiler + superheaters, fans, water treatment, feed pumps) | B2: 1.55 | C2: 0.1 | D2: 0.075 | E2: 0.05 | F2: 0.45 | G2: 3 | H2: 3.55 | I2: 5000 | J2: 150/MW (min 10,000) | K2: =I2*'Currency-Conversion'!$C$10 -> 1.5319397e+10 | L2: =J2&" — تبدیل خودکار به ریال ممکن نشد (نرخ به‌ازای واحد ظرفیت است، نه عدد ساده). برای تبدیل دستی، اعداد را در ضریب "&TEXT('Currency-Conversion'!$C$10,"#,##0")&" ضرب کنید." -> 150/MW (min 10,000) — تبدیل خودکار به ریال ممکن نشد (نرخ به‌ازای واحد ظرفیت است، نه عدد ساده). برای تبدیل دستی، اعداد را در ضریب 3,063,879 ضرب کنید. | N2: 01 — Public Utilities
A3: 01.1.1 Boilerhouse installations comprising boiler with all auxiliaries (superheaters, fans, feed pumps, water treatment) - natural circulat | B3: 1.6 | C3: 0.1 | D3: 0.075 | E3: 0.05 | F3: 0.45 | G3: 3.5 | H3: 3.75 | I3: 5000 | J3: 150/MW | K3: =I3*'Currency-Conversion'!$C$10 -> 1.5319397e+10 | L3: =J3&" — تبدیل خودکار به ریال ممکن نشد (نرخ به‌ازای واحد ظرفیت است، نه عدد ساده). برای تبدیل دستی، اعداد را در ضریب "&TEXT('Currency-Conversion'!$C$10,"#,##0")&" ضرب کنید." -> 150/MW — تبدیل خودکار به ریال ممکن نشد (نرخ به‌ازای واحد ظرفیت است، نه عدد ساده). برای تبدیل دستی، اعداد را در ضریب 3,063,879 ضرب کنید. | N3: 02 — Industrial Plant Utilities
A4: 01.1.2 Turbogenerating sets — turbine, generator, cooling system, governor, directly connected auxiliaries — up to 50 MW | B4: 1.65 | C4: 0.1 | D4: 0.05 | E4: 0.025 | F4: 1 | G4: 10 | H4: 4.4 | I4: 5000 | J4: 25000 | K4: =I4*'Currency-Conversion'!$C$10 -> 1.5319397e+10 | L4: =J4*'Currency-Conversion'!$C$10 -> 76596986250 | N4: 03 — Mining Industry
A5: 01.1.2 Turbogenerating sets (turbine, generator, cooling system, governor, directly connected auxiliaries) — 50 to 125 MW | B5: 1.75 | C5: 0.1 | D5: 0.05 | E5: 0.025 | F5: 1.1 | G5: 10 | H5: 4.75 | I5: 5000 | J5: 250/MW (min 25,000) | K5: =I5*'Currency-Conversion'!$C$10 -> 1.5319397e+10 | L5: =J5&" — تبدیل خودکار به ریال ممکن نشد (نرخ به‌ازای واحد ظرفیت است، نه عدد ساده). برای تبدیل دستی، اعداد را در ضریب "&TEXT('Currency-Conversion'!$C$10,"#,##0")&" ضرب کنید." -> 250/MW (min 25,000) — تبدیل خودکار به ریال ممکن نشد (نرخ به‌ازای واحد ظرفیت است، نه عدد ساده). برای تبدیل دستی، اعداد را در ضریب 3,063,879 ضرب کنید. | N5: 04 — Chemical Industry
A6: 01.1.2 Turbogenerating sets (turbine, generator, cooling system, governor, directly connected auxiliaries) — 125 to 250 MW | B6: 1.75 | C6: 0.1 | D6: 0.05 | E6: 0.025 | F6: 1.3 | G6: 12 | H6: 4.95 | I6: 5000 | J6: 250/MW | K6: =I6*'Currency-Conversion'!$C$10 -> 1.5319397e+10 | L6: =J6&" — تبدیل خودکار به ریال ممکن نشد (نرخ به‌ازای واحد ظرفیت است، نه عدد ساده). برای تبدیل دستی، اعداد را در ضریب "&TEXT('Currency-Conversion'!$C$10,"#,##0")&" ضرب کنید." -> 250/MW — تبدیل خودکار به ریال ممکن نشد (نرخ به‌ازای واحد ظرفیت است، نه عدد ساده). برای تبدیل دستی، اعداد را در ضریب 3,063,879 ضرب کنید. | N6: 05 — Metal Industry
A7: 01.1.2 Turbogenerating sets (turbine, generator, cooling system, governor, directly connected auxiliaries) — 250 to 450 MW | B7: 1.75 | C7: 0.1 | D7: 0.05 | E7: 0.025 | F7: 1.55 | G7: 14 | H7: 5.4 | I7: 7500 | J7: 250/MW | K7: =I7*'Currency-Conversion'!$C$10 -> 2.2979096e+10 | L7: =J7&" — تبدیل خودکار به ریال ممکن نشد (نرخ به‌ازای واحد ظرفیت است، نه عدد ساده). برای تبدیل دستی، اعداد را در ضریب "&TEXT('Currency-Conversion'!$C$10,"#,##0")&" ضرب کنید." -> 250/MW — تبدیل خودکار به ریال ممکن نشد (نرخ به‌ازای واحد ظرفیت است، نه عدد ساده). برای تبدیل دستی، اعداد را در ضریب 3,063,879 ضرب کنید. | N7: 06 — Building Industry
A8: 01.1.3 Water-systems cycle comprising condenser, feed heater piping, pumps etc. | B8: 1.55 | C8: 0.05 | D8: 0.05 | E8: 0.025 | F8: 0.55 | G8: 3 | H8: 3.1 | I8: 2500 | J8: 5000 | K8: =I8*'Currency-Conversion'!$C$10 -> 7.6596986e+09 | L8: =J8*'Currency-Conversion'!$C$10 -> 1.5319397e+10 | N8: 07 — Timber & Wood
A9: 01.1.4 Electric equipment, control and measuring installations incl. station transformers | B9: 1.55 | C9: 0.075 | D9: 0.075 | E9: 0.05 | F9: 0.65 | G9: 3.5 | H9: 3.3 | I9: 2500 | J9: 5000 | K9: =I9*'Currency-Conversion'!$C$10 -> 7.6596986e+09 | L9: =J9*'Currency-Conversion'!$C$10 -> 1.5319397e+10 | N9: 08 — Pulp & Paper
A10: 01.1.5 Balance of plant comprising: ash-handling, off-site tanks | B10: 1.55 | C10: 0.05 | D10: 0.075 | E10: 0.025 | F10: 0.55 | G10: 2 | H10: 3.1 | I10: 2500 | J10: 5000 | K10: =I10*'Currency-Conversion'!$C$10 -> 7.6596986e+09 | L10: =J10*'Currency-Conversion'!$C$10 -> 1.5319397e+10 | N10: 09 — Printing & Packing
A11: 01.2.1 Gas turbine power plants — Gasturbo generating sets (turbine, compressor, generator, starting device, all auxiliaries) — up to 10 MW | B11: 1.65 | C11: 0.15 | D11: 0.075 | E11: 0.05 | F11: 1.1 | G11: 10 | H11: 4.2 | I11: 5000 | J11: 10000 | K11: =I11*'Currency-Conversion'!$C$10 -> 1.5319397e+10 | L11: =J11*'Currency-Conversion'!$C$10 -> 3.0638794e+10 | N11: 10 — Leather Industry
A12: 01.2.1 Gasturbo generating sets (turbine, compressor, generator, starting device, all auxiliaries connected to foundation block) — 10 to 20 | B12: 1.75 | C12: 0.15 | D12: 0.075 | E12: 0.075 | F12: 1.2 | G12: 10 | H12: 4.7 | I12: 5000 | J12: 750/MW (min 10,000) | K12: =I12*'Currency-Conversion'!$C$10 -> 1.5319397e+10 | L12: =J12&" — تبدیل خودکار به ریال ممکن نشد (نرخ به‌ازای واحد ظرفیت است، نه عدد ساده). برای تبدیل دستی، اعداد را در ضریب "&TEXT('Currency-Conversion'!$C$10,"#,##0")&" ضرب کنید." -> 750/MW (min 10,000) — تبدیل خودکار به ریال ممکن نشد (نرخ به‌ازای واحد ظرفیت است، نه عدد ساده). برای تبدیل دستی، اعداد را در ضریب 3,063,879 ضرب کنید. | N12: 11 — Textile Industry
A13: 01.2.1 Gasturbo generating sets (turbine, compressor, generator, starting device, all auxiliaries connected to foundation block) — 20 to 40 | B13: 1.9 | C13: 0.15 | D13: 0.075 | E13: 0.075 | F13: 1.45 | G13: 12 | H13: 5.5 | I13: 5000 | J13: 750/MW | K13: =I13*'Currency-Conversion'!$C$10 -> 1.5319397e+10 | L13: =J13&" — تبدیل خودکار به ریال ممکن نشد (نرخ به‌ازای واحد ظرفیت است، نه عدد ساده). برای تبدیل دستی، اعداد را در ضریب "&TEXT('Currency-Conversion'!$C$10,"#,##0")&" ضرب کنید." -> 750/MW — تبدیل خودکار به ریال ممکن نشد (نرخ به‌ازای واحد ظرفیت است، نه عدد ساده). برای تبدیل دستی، اعداد را در ضریب 3,063,879 ضرب کنید. | N13: 12 — Plastic & Rubber
A14: 01.2.2 Electrical equipment control/measuring: air inlet/outlet, filters, piping, pumps incl. station transformers | B14: 1.55 | C14: 0.075 | D14: 0.075 | E14: 0.075 | F14: 0.65 | G14: 3 | H14: 3.3 | I14: 1000 | J14: 2000 | K14: =I14*'Currency-Conversion'!$C$10 -> 3.0638794e+09 | L14: =J14*'Currency-Conversion'!$C$10 -> 6.1277589e+09 | N14: 13 — Food (Vegetable)
A15: 01.2.3 Balance of plant off-site installations: tanks, gas receiving and/or pressure reducing plant etc. | B15: 1.55 | C15: 0.075 | D15: 0.075 | E15: 0.075 | F15: 0.55 | G15: 2.5 | H15: 3.1 | I15: 1000 | J15: 2000 | K15: =I15*'Currency-Conversion'!$C$10 -> 3.0638794e+09 | L15: =J15*'Currency-Conversion'!$C$10 -> 6.1277589e+09 | N15: 14 — Food (Animal)
A16: 01.3.1 Diesel generator sets — diesel engine, starting device, generator and all auxiliaries attached — engines with speed above 500 rpm | B16: 2.05 | C16: 0.15 | D16: 0.1 | E16: 0.1 | F16: 1.1 | G16: 12 | H16: 4.95 | I16: 2000 | J16: 1000/MW (min 5,000) | K16: =I16*'Currency-Conversion'!$C$10 -> 6.1277589e+09 | L16: =J16&" — تبدیل خودکار به ریال ممکن نشد (نرخ به‌ازای واحد ظرفیت است، نه عدد ساده). برای تبدیل دستی، اعداد را در ضریب "&TEXT('Currency-Conversion'!$C$10,"#,##0")&" ضرب کنید." -> 1000/MW (min 5,000) — تبدیل خودکار به ریال ممکن نشد (نرخ به‌ازای واحد ظرفیت است، نه عدد ساده). برای تبدیل دستی، اعداد را در ضریب 3,063,879 ضرب کنید. | N16: 15 — Food Refrigeration
A17: 01.3.1 Diesel Generator sets (diesel engine, starting device, generator, all attached auxiliaries) - engines with speed above 500 rpm — engi | B17: 1.75 | C17: 0.1 | D17: 0.1 | E17: 0.1 | F17: 0.9 | G17: 10 | H17: 4.2 | I17: 2000 | J17: 1000/MW | K17: =I17*'Currency-Conversion'!$C$10 -> 6.1277589e+09 | L17: =J17&" — تبدیل خودکار به ریال ممکن نشد (نرخ به‌ازای واحد ظرفیت است، نه عدد ساده). برای تبدیل دستی، اعداد را در ضریب "&TEXT('Currency-Conversion'!$C$10,"#,##0")&" ضرب کنید." -> 1000/MW — تبدیل خودکار به ریال ممکن نشد (نرخ به‌ازای واحد ظرفیت است، نه عدد ساده). برای تبدیل دستی، اعداد را در ضریب 3,063,879 ضرب کنید. | N17: 16 — Transport & Warehouses
A18: 01.3.2 Electrical equipment control/measuring; air inlet/outlet, filters, piping, pumps | B18: 1.65 | C18: 0.1 | D18: 0.075 | E18: 0.075 | F18: 0.65 | G18: 3 | H18: 3.4 | I18: 1000 | J18: 2000 | K18: =I18*'Currency-Conversion'!$C$10 -> 3.0638794e+09 | L18: =J18*'Currency-Conversion'!$C$10 -> 6.1277589e+09 | N18: 17 — Public Services
A19: 01.3.3 Balance of plant comprising off-site installations, tanks, etc. | B19: 1.5 | C19: 0.1 | D19: 0.075 | E19: 0.075 | F19: 0.55 | G19: 2.5 | H19: 3 | I19: 1000 | J19: 2000 | K19: =I19*'Currency-Conversion'!$C$10 -> 3.0638794e+09 | L19: =J19*'Currency-Conversion'!$C$10 -> 6.1277589e+09 | N19: 18 — Hospitals & Hotels
A20: 01.4.1 Turbinehouse installations - Pelton turbine, up to 100 MW | B20: 1.55 | C20: 0.075 | D20: 0.05 | E20: 0.025 | F20: 0.65 | G20: 3 | H20: 2.95 | I20: 2500 | J20: 10000 | K20: =I20*'Currency-Conversion'!$C$10 -> 7.6596986e+09 | L20: =J20*'Currency-Conversion'!$C$10 -> 3.0638794e+10 | N20: 19 — Farming & Agriculture
A21: 01.4.1 Turbinehouse installations - Pelton turbine — Pelton, 100 to 200 MW | B21: 1.55 | C21: 0.075 | D21: 0.05 | E21: 0.025 | F21: 0.65 | G21: 4 | H21: 3.3 | I21: 2500 | J21: 100/MW | K21: =I21*'Currency-Conversion'!$C$10 -> 7.6596986e+09 | L21: =J21&" — تبدیل خودکار به ریال ممکن نشد (نرخ به‌ازای واحد ظرفیت است، نه عدد ساده). برای تبدیل دستی، اعداد را در ضریب "&TEXT('Currency-Conversion'!$C$10,"#,##0")&" ضرب کنید." -> 100/MW — تبدیل خودکار به ریال ممکن نشد (نرخ به‌ازای واحد ظرفیت است، نه عدد ساده). برای تبدیل دستی، اعداد را در ضریب 3,063,879 ضرب کنید.
A22: 01.4.1 Turbinehouse installations - Pelton turbine — Francis turbine, up to 100 MW | B22: 1.7 | C22: 0.075 | D22: 0.05 | E22: 0.025 | F22: 0.8 | G22: 3 | H22: 3.3 | I22: 2500 | J22: 10000 | K22: =I22*'Currency-Conversion'!$C$10 -> 7.6596986e+09 | L22: =J22*'Currency-Conversion'!$C$10 -> 3.0638794e+10
A23: 01.4.1 Turbinehouse installations - Pelton turbine — Francis, 100 to 200 MW | B23: 1.8 | C23: 0.075 | D23: 0.05 | E23: 0.025 | F23: 0.8 | G23: 4 | H23: 3.6 | I23: 2500 | J23: 100/MW | K23: =I23*'Currency-Conversion'!$C$10 -> 7.6596986e+09 | L23: =J23&" — تبدیل خودکار به ریال ممکن نشد (نرخ به‌ازای واحد ظرفیت است، نه عدد ساده). برای تبدیل دستی، اعداد را در ضریب "&TEXT('Currency-Conversion'!$C$10,"#,##0")&" ضرب کنید." -> 100/MW — تبدیل خودکار به ریال ممکن نشد (نرخ به‌ازای واحد ظرفیت است، نه عدد ساده). برای تبدیل دستی، اعداد را در ضریب 3,063,879 ضرب کنید.
A24: 01.4.1 Turbinehouse installations - Pelton turbine — Kaplan turbine, up to 100 MW | B24: 1.7 | C24: 0.075 | D24: 0.05 | E24: 0.025 | F24: 0.8 | G24: 4 | H24: 3.3 | I24: 2500 | J24: 10000 | K24: =I24*'Currency-Conversion'!$C$10 -> 7.6596986e+09 | L24: =J24*'Currency-Conversion'!$C$10 -> 3.0638794e+10
A25: 01.4.1 Turbinehouse installations - Pelton turbine — Kaplan, 100 to 200 MW | B25: 1.8 | C25: 0.075 | D25: 0.05 | E25: 0.025 | F25: 0.8 | G25: 4 | H25: 3.65 | I25: 2500 | J25: 100/MW | K25: =I25*'Currency-Conversion'!$C$10 -> 7.6596986e+09 | L25: =J25&" — تبدیل خودکار به ریال ممکن نشد (نرخ به‌ازای واحد ظرفیت است، نه عدد ساده). برای تبدیل دستی، اعداد را در ضریب "&TEXT('Currency-Conversion'!$C$10,"#,##0")&" ضرب کنید." -> 100/MW — تبدیل خودکار به ریال ممکن نشد (نرخ به‌ازای واحد ظرفیت است، نه عدد ساده). برای تبدیل دستی، اعداد را در ضریب 3,063,879 ضرب کنید.
A26: 01.4.1 Turbinehouse installations - Pelton turbine — Other types (tubular/axial flow reaction turbines), up to 25 MW | B26: 1.6 | C26: 0.075 | D26: 0.05 | E26: 0.025 | F26: 0.9 | G26: 4 | H26: 3.3 | I26: 2500 | J26: 5000 | K26: =I26*'Currency-Conversion'!$C$10 -> 7.6596986e+09 | L26: =J26*'Currency-Conversion'!$C$10 -> 1.5319397e+10
A27: 01.4.1 Turbinehouse installations - Pelton turbine — Other types, 25 to 50 MW | B27: 1.7 | C27: 0.075 | D27: 0.05 | E27: 0.025 | F27: 0.9 | G27: 4 | H27: 3.75 | I27: 2500 | J27: 100/MW | K27: =I27*'Currency-Conversion'!$C$10 -> 7.6596986e+09 | L27: =J27&" — تبدیل خودکار به ریال ممکن نشد (نرخ به‌ازای واحد ظرفیت است، نه عدد ساده). برای تبدیل دستی، اعداد را در ضریب "&TEXT('Currency-Conversion'!$C$10,"#,##0")&" ضرب کنید." -> 100/MW — تبدیل خودکار به ریال ممکن نشد (نرخ به‌ازای واحد ظرفیت است، نه عدد ساده). برای تبدیل دستی، اعداد را در ضریب 3,063,879 ضرب کنید.
A28: 01.4.2 Pumping house installations - Horizontal pumping sets, up to 25 MW | B28: 1.75 | C28: 0.1 | D28: 0.075 | E28: 0.05 | F28: 0.8 | G28: 5 | H28: 3.6 | I28: 2500 | J28: 5000 | K28: =I28*'Currency-Conversion'!$C$10 -> 7.6596986e+09 | L28: =J28*'Currency-Conversion'!$C$10 -> 1.5319397e+10
A29: 01.4.2 Pumping house installations - Horizontal pumping sets — Horizontal, 25 to 50 MW | B29: 1.75 | C29: 0.1 | D29: 0.075 | E29: 0.05 | F29: 0.8 | G29: 5 | H29: 4.1 | I29: 2500 | J29: 10000 | K29: =I29*'Currency-Conversion'!$C$10 -> 7.6596986e+09 | L29: =J29*'Currency-Conversion'!$C$10 -> 3.0638794e+10
A30: 01.4.2 Pumping house installations - Horizontal pumping sets — Vertical pumping sets, up to 25 MW | B30: 1.65 | C30: 0.1 | D30: 0.075 | E30: 0.05 | F30: 0.9 | G30: 5 | H30: 3.85 | I30: 2500 | J30: 5000 | K30: =I30*'Currency-Conversion'!$C$10 -> 7.6596986e+09 | L30: =J30*'Currency-Conversion'!$C$10 -> 1.5319397e+10
A31: 01.4.2 Pumping house installations - Horizontal pumping sets — Vertical, 25 to 50 MW | B31: 1.75 | C31: 0.1 | D31: 0.075 | E31: 0.05 | F31: 0.9 | G31: 5 | H31: 4.25 | I31: 2500 | J31: 10000 | K31: =I31*'Currency-Conversion'!$C$10 -> 7.6596986e+09 | L31: =J31*'Currency-Conversion'!$C$10 -> 3.0638794e+10
A32: 01.4.3 Electrical equipment and measuring installations, station transformers, pressurised air control systems, etc. | B32: 1.5 | C32: 0.075 | D32: 0.05 | E32: 0.025 | F32: 0.55 | G32: 3.5 | H32: 3.3 | I32: 2500 | J32: 5000 | K32: =I32*'Currency-Conversion'!$C$10 -> 7.6596986e+09 | L32: =J32*'Currency-Conversion'!$C$10 -> 1.5319397e+10
A33: 01.4.4 Water intake and off-site installations: penstocks, gates, trash racks, weir installations and the like | B33: 1.5 | C33: 0.075 | D33: 0.05 | E33: 0.025 | F33: 0.65 | G33: 3 | H33: 3.3 | I33: 2500 | J33: 5000 | K33: =I33*'Currency-Conversion'!$C$10 -> 7.6596986e+09 | L33: =J33*'Currency-Conversion'!$C$10 -> 1.5319397e+10
A34: 01.5.1 Transformer stations — power transformer, phase compensators, cooling control, capacitors, rectifier banks — 30 to 150 MVA | B34: 1.7 | C34: 0.075 | D34: 0.05 | E34: 0.05 | F34: 0.75 | G34: 5 | H34: 3.15 | I34: 2500 | J34: 5000 | K34: =I34*'Currency-Conversion'!$C$10 -> 7.6596986e+09 | L34: =J34*'Currency-Conversion'!$C$10 -> 1.5319397e+10
A35: 01.5.1 Transformer stations — power transformer, phase compensators, cooling control, capacitors, rectifier banks — 150 to 300 MVA | B35: 1.7 | C35: 0.075 | D35: 0.05 | E35: 0.05 | F35: 0.9 | G35: 6 | H35: 3.4 | I35: 2500 | J35: 5000 | K35: =I35*'Currency-Conversion'!$C$10 -> 7.6596986e+09 | L35: =J35*'Currency-Conversion'!$C$10 -> 1.5319397e+10
A36: 01.5.1 Transformer stations — power transformer, phase compensators, cooling control, capacitors, rectifier banks — above 300 MVA | B36: 1.7 | C36: 0.075 | D36: 0.05 | E36: 0.05 | F36: 1.1 | G36: 7 | H36: 3.65 | I36: 5000 | J36: 10000 | K36: =I36*'Currency-Conversion'!$C$10 -> 1.5319397e+10 | L36: =J36*'Currency-Conversion'!$C$10 -> 3.0638794e+10
A37: 01.5.1 Transformer Stations (power transformer, phase compensators, cooling/control/protection auxiliaries, capacitors, rectifier banks) - P | B37: 1.6 | C37: 0.075 | D37: 0.05 | E37: 0.05 | F37: 0.65 | G37: 5 | H37: 2.9 | I37: 1000 | J37: 2500 | K37: =I37*'Currency-Conversion'!$C$10 -> 3.0638794e+09 | L37: =J37*'Currency-Conversion'!$C$10 -> 7.6596986e+09
A38: 01.5.2 Switchgear installations (circuit breakers, control/protection equipment, line feeders) up to 60 kV | B38: 1.55 | C38: 0.075 | D38: 0.05 | E38: 0.05 | F38: 0.55 | G38: 2 | H38: 2.7 | I38: 1000 | J38: 2500 | K38: =I38*'Currency-Conversion'!$C$10 -> 3.0638794e+09 | L38: =J38*'Currency-Conversion'!$C$10 -> 7.6596986e+09
A39: 01.5.2 Switchgear installations (circuit breakers, control/protection equipment, line feeders) — 60 kV to 500 kV | B39: 1.7 | C39: 0.075 | D39: 0.05 | E39: 0.05 | F39: 0.55 | G39: 2.5 | H39: 2.85 | I39: 1000 | J39: 2500 | K39: =I39*'Currency-Conversion'!$C$10 -> 3.0638794e+09 | L39: =J39*'Currency-Conversion'!$C$10 -> 7.6596986e+09
... A152: 19.3 Poultry farms (rearing hatcheries) and similar installations | B152: 1.55 | C152: 0.125 | D152: 0.075 | E152: 0.05 | F152: 0.55 | G152: 3 | H152: 3.3 | I152: 1000 | J152: 2500 | K152: =I152*'Currency-Conversion'!$C$10 -> 3.0638794e+09 | L152: =J152*'Currency-Conversion'!$C$10 -> 7.6596986e+09
...

Sheet Rate-Clauses
A1: Clause No. | B1: Clause / Endorsement Name | C1: Type | D1: Rate Impact | E1: Basis of Impact | F1: EAR Ref. (Page) | G1: Description & Notes | I1: _clause_list
A2: 1.21.01 | B2: Expediting Costs | C2: Extension | D2: 5-10% of works rate | E2: On total SI | F2: p.35/109 | G2: Covers extra charges for overtime, night-work, public holidays, express freight (excl. airfreight). Limit per event ≈ 20% of expected average claim. | I2: Expediting Costs
A3: 1.21.02 | B3: Cross Liability | C3: Extension | D3: 35% of total TPL prem | E3: On TPL prem | F3: p.42/47 | G3: Allows sub-contractors to claim against each other under same policy. Min 15% if no plant/storage exposure covered separately. | I3: Cross Liability
A4: 1.21.03 | B4: Riot and Strike | C4: Extension | D4: 50% of fire R&S rate | E4: Erection period | F4: p.42/50 | G4: 100% during commissioning/testing period (confirmed, EAR Rating Guide Sec.9 item 6.4). Erection-period % ("50%" previously shown here) could NOT be verified against the uploaded source after two independent searches — flagged as insufficient evidence; use with caution / confirm with reinsurer guideline before relying on it. | I4: Riot and Strike
A5: 1.21.04 | B5: Visits Maintenance | C5: Extension | D5: 5-7.5% of Ref.Rate | E5: Per month | F5: p.41/52 | G5: 5% light industries; 7.5% power plants/chemical/heavy. Cover restricted to damage occurring during contractor site visits. | I5: Visits Maintenance
A6: 1.21.05 | B6: Extended Maintenance | C6: Extension | D6: 7.5-12.5% of Ref.Rate | E6: Per month | F6: p.41/53 | G6: 7.5% light; 12.5% heavy. Full maintenance cover but period usually ≤12 months; loading required for extensions >12 months. | I6: Extended Maintenance
A7: 1.21.06 | B7: [Reserved / Not printed] | C7: N/A | D7: — | E7: — | F7: p.45 | G7: Not printed in the guide copy available. | I7: Contractors' Plant & Equipment
A8: 1.21.07 | B8: [Reserved / Not printed] | C8: N/A | D8: — | E8: — | F8: p.45 | G8: Not printed in the guide copy available. | I8: Airfreight Costs
A9: 1.21.08 | B9: Contractors' Plant & Equipment | C9: Extension | D9: 8-10‰ p.a. (plant) 6-7‰ p.a. (equipment) | E9: Annual rate on SI | F9: p.36/54-55 | G9: Covers mobile/stationary erection plant and scaffolding/hutments. Applies only to smaller, light-type plant. Min excess: 1,000 c-units. If period <1 yr: monthly rate = 1/10 annual rate. | I9: Reassessment Clause — Steam & Gas Turbine Generator Sets
A10: 1.21.09 | B10: Airfreight Costs | C10: Extension | D10: 5-20‰ | E10: On aggregate limit | F10: p.35/56 | G10: 5‰ for distances <2,000 miles; proportional increase to 20‰ for longer. Max aggregate limit ≈ 1% of SI. | I10: Special Conditions — Hydrocarbon Processing Industry
A11: 1.21.10 | B11: [Reserved / Not printed] | C11: N/A | D11: — | E11: — | F11: p.45 | G11: Not printed in available copy. | I11: Faulty Design (Defective Design)
A12: 1.21.11 | B12: [Reserved / Not printed] | C12: N/A | D12: — | E12: — | F12: p.45 | G12: Not printed in available copy. | I12: Existing Property
... A27: — | B27: Contract Works Time Schedule | C27: Special Condition | D27: Condition only | E27: N/A | F27: p.71 | G27: Requires insured to maintain and submit project time schedule. Material deviations may require re-rating. | I27: Third Party Liability (TPL)
A28: — | B28: Debris, Silt, Erosion, Landslip | C28: Extension/Restriction | D28: Per underwriter | E28: On affected SI | F28: p.72 | G28: Adds or restricts cover for debris removal/silt/erosion damage. Terms depend on project type and location.
A29: 6.1.1 | B29: Manufacturer's Risk — Defective Material/Workmanship | C29: Extension | D29: 5/7.5/10% of Ref.Rate | E29: Per test/maint month | F29: Sec 6.1.1 | G29: Additional rate calculated as % of Ref.Rate per testing/maintenance month. Defective part itself always excluded.
A30: 6.1.2 | B30: Manufacturer's Risk — Defective Design | C30: Extension | D30: 5/7.5/10% of Ref.Rate | E30: Per test/maint month | F30: Sec 6.1.2 | G30: Same rate scale as 6.1.1. Only additional repair costs covered (not cost of rectifying the design defect itself).
A31: Table 20 | B31: Third Party Liability (TPL) | C31: Standard Section | D31: 0.20 to 0.80‰ | E31: On contract value | F31: p.186-193 | G31: Rate depends on Technical Risk Category (I/II/III) and Surroundings Category (a/b/c). See Rate-TPL sheet for full rate table.

Sheet Rate-IndividualMachines
A1: EAR Rating — Individual Machines (Blue Tables) | Basic Rate = for up to 3 months erection + 1 month testing | K1: Machine (picker label) | L1: Basic Rate ‰ | M1: Add. Erect ‰/mo | N1: Add. Test ‰/mo | O1: Ref. Rate ‰
A2: EAR Code | B2: Description | C2: Basic Rate (≤3m erection +1m testing) | D2: Add. Rate Erection (per month) | E2: Add. Rate Testing (per month) | F2: Ref. Rate | G2: General Excess (c-units) | H2: AoG/Test/ Maint. XS (c-units) | I2: Gen. Excess (﷼) | J2: Maint. Excess (﷼) | K2: 02.0.1 — Boiler feed pumps, incl. drive — turbine driven | L2: 4 | M2: 0.25 | N2: 1 | O2: 12
A3: 01.0 | B3: PUBLIC UTILITIES — Individual machines: use min rate from white Rating Table 01 (Public Utilities) or white Table 16 (Transport) | K3: 02.0.1 — Boiler feed pumps, incl. drive — motor driven | L3: 3.5 | M3: 0.2 | N3: 0.8 | O3: 8
A4: 02.0 | B4: UTILITIES IN INDUSTRIAL PLANTS — Individual Machines | K4: 02.0.2 — Heat exchangers, condensers | L4: 2.5 | M4: 0.1 | N4: 0.3 | O4: 4
A5: 02.0.1 | B5: Boiler feed pumps, incl. drive — turbine driven | C5: 4 | D5: 0.25 | E5: 1 | F5: 12 | G5: 2500 | H5: 10000 | I5: =G5*'Currency-Conversion'!$C$10 -> 7.6596986e+09 | J5: =H5*'Currency-Conversion'!$C$10 -> 3.0638794e+10 | K5: 02.0.3 — Electrical motors — asynchronous squirrel cage, up to 1 MW | L5: 2.5 | M5: 0.1 | N5: 0.6 | O5: 5
A6: 02.0.1 | B6: Boiler feed pumps, incl. drive — motor driven | C6: 3.5 | D6: 0.2 | E6: 0.8 | F6: 8 | G6: 1250 | H6: 2500 | I6: =G6*'Currency-Conversion'!$C$10 -> 3.8298493e+09 | J6: =H6*'Currency-Conversion'!$C$10 -> 7.6596986e+09 | K6: 02.0.3 — Electrical motors — asynchronous slip ring, up to 25 MW | L6: 2.7 | M6: 0.1 | N6: 0.8 | O6: 6
A7: 02.0.2 | B7: Heat exchangers, condensers | C7: 2.5 | D7: 0.1 | E7: 0.3 | F7: 4 | G7: 500 | H7: 1000 | I7: =G7*'Currency-Conversion'!$C$10 -> 1.5319397e+09 | J7: =H7*'Currency-Conversion'!$C$10 -> 3.0638794e+09 | K7: 02.0.3 — Electrical motors — synchronous, up to 25 MW | L7: 3 | M7: 0.15 | N7: 0.9 | O7: 6
A8: 02.0.3 | B8: Electrical motors — asynchronous squirrel cage, up to 1 MW | C8: 2.5 | D8: 0.1 | E8: 0.6 | F8: 5 | G8: 500 | H8: 1000 | I8: =G8*'Currency-Conversion'!$C$10 -> 1.5319397e+09 | J8: =H8*'Currency-Conversion'!$C$10 -> 3.0638794e+09 | K8: 02.0.3 — Electrical motors — direct current, up to 10 MW | L8: 3.5 | M8: 0.15 | N8: 1 | O8: 8
A9: 02.0.3 | B9: Electrical motors — asynchronous slip ring, up to 25 MW | C9: 2.7 | D9: 0.1 | E9: 0.8 | F9: 6 | G9: 500 | H9: 1000 | I9: =G9*'Currency-Conversion'!$C$10 -> 1.5319397e+09 | J9: =H9*'Currency-Conversion'!$C$10 -> 3.0638794e+09 | K9: 02.0.3 — Electrical motors — special design (e.g. ring motor), up to 25 MW | L9: 4 | M9: 0.2 | N9: 1 | O9: 8
A10: 02.0.3 | B10: Electrical motors — synchronous, up to 25 MW | C10: 3 | D10: 0.15 | E10: 0.9 | F10: 6 | G10: 500 | H10: 1000 | I10: =G10*'Currency-Conversion'!$C$10 -> 1.5319397e+09 | J10: =H10*'Currency-Conversion'!$C$10 -> 3.0638794e+09 | K10: 02.0.4 — Transformers — single/three phase, up to 100 MW; 30 kV | L10: 3 | M10: 0.2 | N10: 0.7 | O10: 6
A11: 02.0.3 | B11: Electrical motors — direct current, up to 10 MW | C11: 3.5 | D11: 0.15 | E11: 1 | F11: 8 | G11: 1000 | H11: 2000 | I11: =G11*'Currency-Conversion'!$C$10 -> 3.0638794e+09 | J11: =H11*'Currency-Conversion'!$C$10 -> 6.1277589e+09 | K11: 02.0.4 — Transformers — special design (rectifier/furnace transformers), up to 50 MW | L11: 3.5 | M11: 0.25 | N11: 1 | O11: 6
A12: 02.0.3 | B12: Electrical motors — special design (e.g. ring motor), up to 25 MW | C12: 4 | D12: 0.2 | E12: 1 | F12: 8 | G12: 2500 | H12: 5000 | I12: =G12*'Currency-Conversion'!$C$10 -> 7.6596986e+09 | J12: =H12*'Currency-Conversion'!$C$10 -> 1.5319397e+10 | K12: 02.0.5 — Pumps incl. motor drive — reciprocating type, up to 5 MW; 50 bar | L12: 3 | M12: 0.25 | N12: 0.8 | O12: 10
A13: 02.0.4 | B13: Transformers — single/three phase, up to 100 MW; 30 kV | C13: 3 | D13: 0.2 | E13: 0.7 | F13: 6 | G13: 1000 | H13: 2000 | I13: =G13*'Currency-Conversion'!$C$10 -> 3.0638794e+09 | J13: =H13*'Currency-Conversion'!$C$10 -> 6.1277589e+09 | K13: 02.0.5 — Pumps incl. motor drive — centrifugal type, up to 5 MW; 50 bar | L13: 3.3 | M13: 0.25 | N13: 0.7 | O13: 6
A14: 02.0.4 | B14: Transformers — special design (rectifier/furnace transformers), up to 50 MW | C14: 3.5 | D14: 0.25 | E14: 1 | F14: 6 | G14: 2000 | H14: 4000 | I14: =G14*'Currency-Conversion'!$C$10 -> 6.1277589e+09 | J14: =H14*'Currency-Conversion'!$C$10 -> 1.2255518e+10 | K14: 02.0.5 — Pumps incl. motor drive — special design (submerged, deepwell) | L14: 3.5 | M14: 0.3 | N14: 1 | O14: 8
A15: 02.0.5 | B15: Pumps incl. motor drive — reciprocating type, up to 5 MW; 50 bar | C15: 3 | D15: 0.25 | E15: 0.8 | F15: 10 | G15: 1000 | H15: 2000 | I15: =G15*'Currency-Conversion'!$C$10 -> 3.0638794e+09 | J15: =H15*'Currency-Conversion'!$C$10 -> 6.1277589e+09 | K15: 02.0.6 — Compressors incl. drive — reciprocating, up to 10 MW; 100 bar | L15: 3.7 | M15: 0.2 | N15: 0.75 | O15: 10
A16: 02.0.5 | B16: Pumps incl. motor drive — centrifugal type, up to 5 MW; 50 bar | C16: 3.3 | D16: 0.25 | E16: 0.7 | F16: 6 | G16: 1000 | H16: 2000 | I16: =G16*'Currency-Conversion'!$C$10 -> 3.0638794e+09 | J16: =H16*'Currency-Conversion'!$C$10 -> 6.1277589e+09 | K16: 02.0.6 — Compressors — turbo (axial/radial), turbine driven, up to 10 MW; 50 bar | L16: 4 | M16: 0.25 | N16: 1 | O16: 15
... A22: 02.0.8 | B22: Other individual machines, not specified elsewhere | C22: 2.5 | D22: 0.2 | E22: 0.4 | F22: 5 | G22: 500 | H22: 1000 | I22: =G22*'Currency-Conversion'!$C$10 -> 1.5319397e+09 | J22: =H22*'Currency-Conversion'!$C$10 -> 3.0638794e+09 | K22: 03.0.3 — Hoists, shaft lifts | L22: 2.5 | M22: 0.2 | N22: 0.6 | O22: 6
A23: 03.0 | B23: MINING INDUSTRY — Individual Machines | K23: 03.0.4 — Compressors/ventilators incl. drive — turbine driven, up to 10 000 kW; 50 bar | L23: 3 | M23: 0.3 | N23: 1 | O23: 10
A24: 03.0.1 | B24: Dredgers, excavators, draglines and other exploitation machines | C24: 4 | D24: 0.3 | E24: 1 | F24: 15 | G24: 5000 | H24: 10000 | I24: =G24*'Currency-Conversion'!$C$10 -> 1.5319397e+10 | J24: =H24*'Currency-Conversion'!$C$10 -> 3.0638794e+10 | K24: 03.0.4 — Compressors/ventilators incl. drive — motor driven, up to 10 000 kW; 50 bar | L24: 3.5 | M24: 0.2 | N24: 1.25 | O24: 15
A25: 03.0.2 | B25: Breakers, crushers | C25: 3.5 | D25: 0.25 | E25: 1.5 | F25: 25 | G25: 2500 | H25: 5000 | I25: =G25*'Currency-Conversion'!$C$10 -> 7.6596986e+09 | J25: =H25*'Currency-Conversion'!$C$10 -> 1.5319397e+10 | K25: 03.0.5 — Kilns, reverberatory furnaces, pelletizers | L25: 3 | M25: 0.15 | N25: 0.5 | O25: 6
A26: 03.0.3 | B26: Hoists, shaft lifts | C26: 2.5 | D26: 0.2 | E26: 0.6 | F26: 6 | G26: 1000 | H26: 2000 | I26: =G26*'Currency-Conversion'!$C$10 -> 3.0638794e+09 | J26: =H26*'Currency-Conversion'!$C$10 -> 6.1277589e+09 | K26: 03.0.6 — Other individual machines, not specified elsewhere | L26: 2.5 | M26: 0.1 | N26: 0.5 | O26: 5
A27: 03.0.4 | B27: Compressors/ventilators incl. drive — turbine driven, up to 10 000 kW; 50 bar | C27: 3 | D27: 0.3 | E27: 1 | F27: 10 | G27: 5000 | H27: 10000 | I27: =G27*'Currency-Conversion'!$C$10 -> 1.5319397e+10 | J27: =H27*'Currency-Conversion'!$C$10 -> 3.0638794e+10 | K27: 04.0.1 — Vessels, pressure vessels, distallation columns, crackers, reactors, furnaces | L27: 3.2 | M27: 0.25 | N27: 0.6 | O27: 6
A28: 03.0.4 | B28: Compressors/ventilators incl. drive — motor driven, up to 10 000 kW; 50 bar | C28: 3.5 | D28: 0.2 | E28: 1.25 | F28: 15 | G28: 2500 | H28: 5000 | I28: =G28*'Currency-Conversion'!$C$10 -> 7.6596986e+09 | J28: =H28*'Currency-Conversion'!$C$10 -> 1.5319397e+10 | K28: 04.0.2 — Turbo-compressors/pumps — turbine driven, ≤100 MW; ≤100 bar | L28: 5.5 | M28: 0.3 | N28: 1.5 | O28: 18
A29: 03.0.5 | B29: Kilns, reverberatory furnaces, pelletizers | C29: 3 | D29: 0.15 | E29: 0.5 | F29: 6 | G29: 2500 | H29: 5000 | I29: =G29*'Currency-Conversion'!$C$10 -> 7.6596986e+09 | J29: =H29*'Currency-Conversion'!$C$10 -> 1.5319397e+10 | K29: 04.0.2 — Turbo-compressors/pumps — motor driven, ≤100 MW; ≤100 bar | L29: 4.25 | M29: 0.25 | N29: 0.9 | O29: 12
A30: 03.0.6 | B30: Other individual machines, not specified elsewhere | C30: 2.5 | D30: 0.1 | E30: 0.5 | F30: 5 | G30: 1000 | H30: 2000 | I30: =G30*'Currency-Conversion'!$C$10 -> 3.0638794e+09 | J30: =H30*'Currency-Conversion'!$C$10 -> 6.1277589e+09 | K30: 04.0.3 — Reciprocating type compressors and pumps — motor driven, ≤20 MW; ≤250 bar | L30: 3.85 | M30: 0.25 | N30: 0.75 | O30: 10
A31: 04.0 | B31: CHEMICAL INDUSTRY — Individual Machines | K31: 04.0.4 — Centrifuges | L31: 3.2 | M31: 0.2 | N31: 0.45 | O31: 5
A32: 04.0.1 | B32: Vessels, pressure vessels, distallation columns, crackers, reactors, furnaces | C32: 3.2 | D32: 0.25 | E32: 0.6 | F32: 6 | G32: 2500 | H32: 5000 | I32: =G32*'Currency-Conversion'!$C$10 -> 7.6596986e+09 | J32: =H32*'Currency-Conversion'!$C$10 -> 1.5319397e+10 | K32: 04.0.5 — Filters, cyclones, electrostatic precipitators | L32: 3.2 | M32: 0.15 | N32: 0.8 | O32: 6
A33: 04.0.2 | B33: Turbo-compressors/pumps — turbine driven, ≤100 MW; ≤100 bar | C33: 5.5 | D33: 0.3 | E33: 1.5 | F33: 18 | G33: 2500 | H33: 10000 | I33: =G33*'Currency-Conversion'!$C$10 -> 7.6596986e+09 | J33: =H33*'Currency-Conversion'!$C$10 -> 3.0638794e+10 | K33: 04.0.6 — Other individual machines, not specified elsewhere | L33: 2.75 | M33: 0.15 | N33: 0.4 | O33: 4
A34: 04.0.2 | B34: Turbo-compressors/pumps — motor driven, ≤100 MW; ≤100 bar | C34: 4.25 | D34: 0.25 | E34: 0.9 | F34: 12 | G34: 2500 | H34: 5000 | I34: =G34*'Currency-Conversion'!$C$10 -> 7.6596986e+09 | J34: =H34*'Currency-Conversion'!$C$10 -> 1.5319397e+10 | K34: 05.0.1 — Steel furnaces (Bessemer and Thomas converters, Siemens Martin furnaces) | L34: 2.7 | M34: 0.2 | N34: 0.4 | O34: 5
A35: 04.0.3 | B35: Reciprocating type compressors and pumps — motor driven, ≤20 MW; ≤250 bar | C35: 3.85 | D35: 0.25 | E35: 0.75 | F35: 10 | G35: 2000 | H35: 2000 | I35: =G35*'Currency-Conversion'!$C$10 -> 6.1277589e+09 | J35: =H35*'Currency-Conversion'!$C$10 -> 6.1277589e+09 | K35: 05.0.2 — Electrical arc furnaces | L35: 2.85 | M35: 0.25 | N35: 0.5 | O35: 6
A36: 04.0.4 | B36: Centrifuges | C36: 3.2 | D36: 0.2 | E36: 0.45 | F36: 5 | G36: 500 | H36: 1000 | I36: =G36*'Currency-Conversion'!$C$10 -> 1.5319397e+09 | J36: =H36*'Currency-Conversion'!$C$10 -> 3.0638794e+09 | K36: 05.0.3 — Other furnaces | L36: 2.5 | M36: 0.2 | N36: 0.4 | O36: 5
A37: 04.0.5 | B37: Filters, cyclones, electrostatic precipitators | C37: 3.2 | D37: 0.15 | E37: 0.8 | F37: 6 | G37: 2500 | H37: 5000 | I37: =G37*'Currency-Conversion'!$C$10 -> 7.6596986e+09 | J37: =H37*'Currency-Conversion'!$C$10 -> 1.5319397e+10 | K37: 05.0.4 — Hot rolling mills, continuous casting machines | L37: 3 | M37: 0.2 | N37: 0.5 | O37: 6
A38: 04.0.6 | B38: Other individual machines, not specified elsewhere | C38: 2.75 | D38: 0.15 | E38: 0.4 | F38: 4 | G38: 500 | H38: 1000 | I38: =G38*'Currency-Conversion'!$C$10 -> 1.5319397e+09 | J38: =H38*'Currency-Conversion'!$C$10 -> 3.0638794e+09 | K38: 05.0.5 — Extrusion presses, forging hammers, forging presses, shears and punching machines, presses, cutters | L38: 3.1 | M38: 0.2 | N38: 0.6 | O38: 8
A39: 05.0 | B39: METAL INDUSTRY — Individual Machines | K39: 05.0.6 — Cold rolling mills | L39: 2.85 | M39: 0.2 | N39: 0.5 | O39: 5
A40: 05.0.1 | B40: Steel furnaces (Bessemer and Thomas converters, Siemens Martin furnaces) | C40: 2.7 | D40: 0.2 | E40: 0.4 | F40: 5 | G40: 2500 | H40: 5000 | I40: =G40*'Currency-Conversion'!$C$10 -> 7.6596986e+09 | J40: =H40*'Currency-Conversion'!$C$10 -> 1.5319397e+10 | K40: 05.0.7 — Machine tools, incl. NC equipment, lathes, planing etc. | L40: 2.2 | M40: 0.15 | N40: 0.35 | O40: 4
A41: 05.0.2 | B41: Electrical arc furnaces | C41: 2.85 | D41: 0.25 | E41: 0.5 | F41: 6 | G41: 2500 | H41: 5000 | I41: =G41*'Currency-Conversion'!$C$10 -> 7.6596986e+09 | J41: =H41*'Currency-Conversion'!$C$10 -> 1.5319397e+10 | K41: 05.0.8 — Scrap shearing machines, shredders | L41: 2.5 | M41: 0.25 | N41: 0.5 | O41: 5
A42: 05.0.3 | B42: Other furnaces | C42: 2.5 | D42: 0.2 | E42: 0.4 | F42: 5 | G42: 2500 | H42: 5000 | I42: =G42*'Currency-Conversion'!$C$10 -> 7.6596986e+09 | J42: =H42*'Currency-Conversion'!$C$10 -> 1.5319397e+10 | K42: 05.0.9 — Other individual machines, not specified elsewhere | L42: 2.3 | M42: 0.15 | N42: 0.4 | O42: 4
A43: 05.0.4 | B43: Hot rolling mills, continuous casting machines | C43: 3 | D43: 0.2 | E43: 0.5 | F43: 6 | G43: 2500 | H43: 5000 | I43: =G43*'Currency-Conversion'!$C$10 -> 7.6596986e+09 | J43: =H43*'Currency-Conversion'!$C$10 -> 1.5319397e+10 | K43: 06.0.1 — Crushers (hammer, jaw) | L43: 4.5 | M43: 0.1 | N43: 1.5 | O43: 20
A44: 05.0.5 | B44: Extrusion presses, forging hammers, forging presses, shears and punching machines, presses, cutters | C44: 3.1 | D44: 0.2 | E44: 0.6 | F44: 8 | G44: 2500 | H44: 5000 | I44: =G44*'Currency-Conversion'!$C$10 -> 7.6596986e+09 | J44: =H44*'Currency-Conversion'!$C$10 -> 1.5319397e+10 | K44: 06.0.2 — Transport systems: conveyor belts, bucket elevators, air slides, air lifts | L44: 2.8 | M44: 0.15 | N44: 0.4 | O44: 5
A45: 05.0.6 | B45: Cold rolling mills | C45: 2.85 | D45: 0.2 | E45: 0.5 | F45: 5 | G45: 1250 | H45: 2500 | I45: =G45*'Currency-Conversion'!$C$10 -> 3.8298493e+09 | J45: =H45*'Currency-Conversion'!$C$10 -> 7.6596986e+09 | K45: 06.0.3 — Mills: raw material grinding, clinker grinding, coal grinding, mixers | L45: 3.4 | M45: 0.15 | N45: 0.5 | O45: 6
...

Sheet Rate-TPL
A1: EAR Rating — Third Party Liability (TPL) Section | Rating Guidelines Swiss Re EAR-Policy | Base: 2 million c-units limit, excess 2,000 c-units
A2: B.1 TABLE OF RATES FOR BASIC LIMIT (2 mio c-units, excess 2,000 c-units)
A3: Tech. Risk Cat. | B3: Industry Examples | C3: Surroundings Category a (isolated site) | D3: Surroundings Category b (outer town) | E3: Surroundings Category c (dense/urban) | F3: Min.Prem. a (c-units) | G3: Min.Prem. b (c-units) | H3: Min.Prem. c (c-units) | I3: Min.Prem. a (﷼) | J3: Min.Prem. b (﷼) | K3: Min.Prem. c (﷼)
A4: I (Light) | B4: 09 Printing, 10 Leather, 11 Textile, 13 Food (veg), 14 Food (anim) | C4: 0.2 | D4: 0.3 | E4: 0.4 | F4: 500 | G4: 800 | H4: 1500 | I4: =F4*'Currency-Conversion'!$C$10 -> 1.5319397e+09 | J4: =G4*'Currency-Conversion'!$C$10 -> 2451103560 | K4: =H4*'Currency-Conversion'!$C$10 -> 4595819175
A5: II (Medium) | B5: 01.5 Electricity dist., 01.6 Waterworks, 01.8 Telecom, 07 Timber, 08 Paper, 12 Plastic, 15 Cold stores, 17 Public svcs, 18 Hospitals, 19 Farming | C5: 0.3 | D5: 0.45 | E5: 0.6 | F5: 1300 | G5: 1800 | H5: 2500 | I5: =F5*'Currency-Conversion'!$C$10 -> 3.9830433e+09 | J5: =G5*'Currency-Conversion'!$C$10 -> 5.514983e+09 | K5: =H5*'Currency-Conversion'!$C$10 -> 7.6596986e+09
A6: III (Heavy) | B6: 01.1-.4 Power plants, 01.7 Garbage, 02 Indust. utilities, 03 Mining, 04 Chemical, 05 Metal, 06 Building, 12 Plastic, 16 Transport/ports | C6: 0.4 | D6: 0.6 | E6: 0.8 | F6: 2300 | G6: 2900 | H6: 4000 | I6: =F6*'Currency-Conversion'!$C$10 -> 7.0469227e+09 | J6: =G6*'Currency-Conversion'!$C$10 -> 8885250405 | K6: =H6*'Currency-Conversion'!$C$10 -> 1.2255518e+10
A7: B.2 FACTORS FOR ADAPTING RATES TO OTHER LIMITS (minimum excess = 1 ‰ of total limit)
A8: Total Limit (c-units mio) | B8: Factor | I8: Notes
A9: ≤ 0.5 mio | B9: 0.65
A10: 1 mio | B10: 0.8
A11: 2 mio (base) | B11: 1
A12: 4 mio | B12: 1.2
A13: 6 mio | B13: 1.4
A14: 8 mio | B14: 1.56
A15: 10 mio | B15: 1.67
A16: B.3 REBATES FOR INCREASED EXCESSES (excess in ‰ of total limit insured)
A17: Excess (‰ of total limit insured) | B17: Deduction (% of total premium) | I17: Notes
A18: 1 ‰ (min) | B18: 0% (no rebate)
A19: 2 ‰ | B19: 10%
A20: 3 ‰ | B20: 15%
A21: 5 ‰ | B21: 20%
A22: B.4 ADDITIONAL PREMIUM FOR TPL COVER DURING MAINTENANCE PERIOD
A23: Maintenance Type | B23: Additional Premium | I23: Notes
A24: Visits maintenance (12-month period) | B24: 20% of TPL rate for erection/testing (pro rata for longer periods)
A25: Extended maintenance (12-month period) | B25: 40% of TPL rate for erection/testing (pro rata for longer periods)
A26: B.5 ADDITIONAL PREMIUM FOR CROSS LIABILITY
A27: Surcharge: 35% of total TPL premium (minimum 15% if no plant/equipment/storage exposure or these are covered under MD section)
A28: B.6 DEDUCTIONS OF PREMIUM RATES FOR HIGH CONTRACT (PROJECT) VALUES
A29: Contract Value | B29: Rebate on TPL Rate | I29: Notes
A30: Up to c-units 50 mio | B30: None
A31: 50 mio to 150 mio | B31: 0 – 15%
A32: 150 mio to 350 mio | B32: 15 – 40%
A33: Above 350 mio | B33: Case by case

Sheet Rate-Deductibles
A1: EAR — Excess / Deductible Reference Tables (Swiss Re EAR Rating Guide — Section 9)
A2: D.1 REBATE FACTORS — MULTIPLES OF MINIMUM EXCESS (applied to individual item rate)
A3: Multiple of Min. Excess | B3: Rebate Factor (× basic rate) | C3: Effective Rate = | G3: Notes
A4: 2 | B4: 0.9 | C4: basic rate × 0.9
A5: 3 | B5: 0.85 | C5: basic rate × 0.85
A6: 5 | B6: 0.8 | C6: basic rate × 0.8
A7: 7.5 | B7: 0.75 | C7: basic rate × 0.75
A8: 10 | B8: 0.7 | C8: basic rate × 0.7
A9: 20 | B9: 0.65 | C9: basic rate × 0.65
A10: 30 | B10: 0.6 | C10: basic rate × 0.6
A11: 40 | B11: 0.55 | C11: basic rate × 0.55
A12: 60 | B12: 0.5 | C12: basic rate × 0.5
A13: 100 | B13: 0.45 | C13: basic rate × 0.45
A14: > 100 | B14: Consult Reinsurer
A15: D.2 PROPORTIONAL EXCESS (% of each claim)
A16: Proportional Excess (% of each claim) | B16: Rebate Factor | G16: Notes
A17: 10% | B17: 0.9
A18: 20% | B18: 0.8
A19: D.3 MINIMUM EXCESSES BY SUB-GROUP (from white Rating Tables — Source: Rate-SubGroup col G = Ref.Rate, col H = EAR source)
A20: Row | B20: Sub-Group Name (EAR Standard) | C20: Min. Rate | D20: Gen. Excess (c-units) All Events | E20: AoG/Test/Maint. Excess (c-units) | F20: EAR Table Source | G20: Notes | H20: Gen. Excess (﷼) | I20: AoG Excess (﷼)
A21: 1 | B21: 01.1.1 Boilerhouse installations — natural circulation, ≤250 t/h (boiler + superheaters, fans, water treatment, feed pumps) | C21: 3.55 | D21: 5000 | E21: 150/MW (min 10,000) | F21: Rate-SubGroup row 2 | H21: =D21*'Currency-Conversion'!$C$10 -> 1.5319397e+10 | I21: =E21&" — تبدیل خودکار ممکن نشد (نرخ به‌ازای واحد ظرفیت)." -> 150/MW (min 10,000) — تبدیل خودکار ممکن نشد (نرخ به‌ازای واحد ظرفیت).
A22: 2 | B22: 01.1.1 Boilerhouse installations comprising boiler with all auxiliaries (superheaters, fans, feed pumps, water treatment) - natural circulat | C22: 3.75 | D22: 5000 | E22: 150/MW | F22: Rate-SubGroup row 3 | H22: =D22*'Currency-Conversion'!$C$10 -> 1.5319397e+10 | I22: =E22&" — تبدیل خودکار ممکن نشد (نرخ به‌ازای واحد ظرفیت)." -> 150/MW — تبدیل خودکار ممکن نشد (نرخ به‌ازای واحد ظرفیت).
A23: 3 | B23: 01.1.2 Turbogenerating sets — turbine, generator, cooling system, governor, directly connected auxiliaries — up to 50 MW | C23: 4.4 | D23: 5000 | E23: 25000 | F23: Rate-SubGroup row 4 | H23: =D23*'Currency-Conversion'!$C$10 -> 1.5319397e+10 | I23: =E23*'Currency-Conversion'!$C$10 -> 76596986250
A24: 4 | B24: 01.1.2 Turbogenerating sets (turbine, generator, cooling system, governor, directly connected auxiliaries) — 50 to 125 MW | C24: 4.75 | D24: 5000 | E24: 250/MW (min 25,000) | F24: Rate-SubGroup row 5 | H24: =D24*'Currency-Conversion'!$C$10 -> 1.5319397e+10 | I24: =E24&" — تبدیل خودکار ممکن نشد (نرخ به‌ازای واحد ظرفیت)." -> 250/MW (min 25,000) — تبدیل خودکار ممکن نشد (نرخ به‌ازای واحد ظرفیت).
A25: 5 | B25: 01.1.2 Turbogenerating sets (turbine, generator, cooling system, governor, directly connected auxiliaries) — 125 to 250 MW | C25: 4.95 | D25: 5000 | E25: 250/MW | F25: Rate-SubGroup row 6 | H25: =D25*'Currency-Conversion'!$C$10 -> 1.5319397e+10 | I25: =E25&" — تبدیل خودکار ممکن نشد (نرخ به‌ازای واحد ظرفیت)." -> 250/MW — تبدیل خودکار ممکن نشد (نرخ به‌ازای واحد ظرفیت).
A26: 6 | B26: 01.1.2 Turbogenerating sets (turbine, generator, cooling system, governor, directly connected auxiliaries) — 250 to 450 MW | C26: 5.4 | D26: 7500 | E26: 250/MW | F26: Rate-SubGroup row 7 | H26: =D26*'Currency-Conversion'!$C$10 -> 2.2979096e+10 | I26: =E26&" — تبدیل خودکار ممکن نشد (نرخ به‌ازای واحد ظرفیت)." -> 250/MW — تبدیل خودکار ممکن نشد (نرخ به‌ازای واحد ظرفیت).
A27: 7 | B27: 01.1.3 Water-systems cycle comprising condenser, feed heater piping, pumps etc. | C27: 3.1 | D27: 2500 | E27: 5000 | F27: Rate-SubGroup row 8 | H27: =D27*'Currency-Conversion'!$C$10 -> 7.6596986e+09 | I27: =E27*'Currency-Conversion'!$C$10 -> 1.5319397e+10
A28: 8 | B28: 01.1.4 Electric equipment, control and measuring installations incl. station transformers | C28: 3.3 | D28: 2500 | E28: 5000 | F28: Rate-SubGroup row 9 | H28: =D28*'Currency-Conversion'!$C$10 -> 7.6596986e+09 | I28: =E28*'Currency-Conversion'!$C$10 -> 1.5319397e+10
A29: 9 | B29: 01.1.5 Balance of plant comprising: ash-handling, off-site tanks | C29: 3.1 | D29: 2500 | E29: 5000 | F29: Rate-SubGroup row 10 | H29: =D29*'Currency-Conversion'!$C$10 -> 7.6596986e+09 | I29: =E29*'Currency-Conversion'!$C$10 -> 1.5319397e+10
A30: 10 | B30: 01.2.1 Gas turbine power plants — Gasturbo generating sets (turbine, compressor, generator, starting device, all auxiliaries) — up to 10 MW | C30: 4.2 | D30: 5000 | E30: 10000 | F30: Rate-SubGroup row 11 | H30: =D30*'Currency-Conversion'!$C$10 -> 1.5319397e+10 | I30: =E30*'Currency-Conversion'!$C$10 -> 3.0638794e+10
A31: 11 | B31: 01.2.1 Gasturbo generating sets (turbine, compressor, generator, starting device, all auxiliaries connected to foundation block) — 10 to 20 | C31: 4.7 | D31: 5000 | E31: 750/MW (min 10,000) | F31: Rate-SubGroup row 12 | H31: =D31*'Currency-Conversion'!$C$10 -> 1.5319397e+10 | I31: =E31&" — تبدیل خودکار ممکن نشد (نرخ به‌ازای واحد ظرفیت)." -> 750/MW (min 10,000) — تبدیل خودکار ممکن نشد (نرخ به‌ازای واحد ظرفیت).
A32: 12 | B32: 01.2.1 Gasturbo generating sets (turbine, compressor, generator, starting device, all auxiliaries connected to foundation block) — 20 to 40 | C32: 5.5 | D32: 5000 | E32: 750/MW | F32: Rate-SubGroup row 13 | H32: =D32*'Currency-Conversion'!$C$10 -> 1.5319397e+10 | I32: =E32&" — تبدیل خودکار ممکن نشد (نرخ به‌ازای واحد ظرفیت)." -> 750/MW — تبدیل خودکار ممکن نشد (نرخ به‌ازای واحد ظرفیت).
